<?xml version="1.0" encoding="UTF-8"?>
<testng-results skipped="0" failed="3" ignored="0" total="5" passed="2">
  <reporter-output>
  </reporter-output>
  <suite name="Default suite" duration-ms="7186" started-at="2022-01-03T00:57:04 BRT" finished-at="2022-01-03T00:57:11 BRT">
    <groups>
    </groups>
    <test name="Default test" duration-ms="7186" started-at="2022-01-03T00:57:04 BRT" finished-at="2022-01-03T00:57:11 BRT">
      <class name="testes.TesteApiDummy">
        <test-method status="PASS" signature="test1_getAllEmployee()[pri:0, instance:testes.TesteApiDummy@51cdd8a]" name="test1_getAllEmployee" duration-ms="3041" started-at="2022-01-03T00:57:04 BRT" finished-at="2022-01-03T00:57:07 BRT">
          <reporter-output>
          </reporter-output>
        </test-method> <!-- test1_getAllEmployee -->
        <test-method status="FAIL" signature="test2_postEmployee()[pri:0, instance:testes.TesteApiDummy@51cdd8a]" name="test2_postEmployee" duration-ms="1058" started-at="2022-01-03T00:57:07 BRT" finished-at="2022-01-03T00:57:08 BRT">
          <exception class="java.lang.AssertionError">
            <message>
              <![CDATA[expected:<429> but was:<200>]]>
            </message>
            <full-stacktrace>
              <![CDATA[java.lang.AssertionError: expected:<429> but was:<200>
at org.junit.Assert.fail(Assert.java:88)
at org.junit.Assert.failNotEquals(Assert.java:834)
at org.junit.Assert.assertEquals(Assert.java:645)
at org.junit.Assert.assertEquals(Assert.java:631)
at testes.TesteApiDummy.test2_postEmployee(TesteApiDummy.java:51)
at sun.reflect.NativeMethodAccessorImpl.invoke0(Native Method)
at sun.reflect.NativeMethodAccessorImpl.invoke(NativeMethodAccessorImpl.java:62)
at sun.reflect.DelegatingMethodAccessorImpl.invoke(DelegatingMethodAccessorImpl.java:43)
at java.lang.reflect.Method.invoke(Method.java:498)
at org.testng.internal.MethodInvocationHelper.invokeMethod(MethodInvocationHelper.java:133)
at org.testng.internal.TestInvoker.invokeMethod(TestInvoker.java:584)
at org.testng.internal.TestInvoker.invokeTestMethod(TestInvoker.java:172)
at org.testng.internal.MethodRunner.runInSequence(MethodRunner.java:46)
at org.testng.internal.TestInvoker$MethodInvocationAgent.invoke(TestInvoker.java:804)
at org.testng.internal.TestInvoker.invokeTestMethods(TestInvoker.java:145)
at org.testng.internal.TestMethodWorker.invokeTestMethods(TestMethodWorker.java:146)
at org.testng.internal.TestMethodWorker.run(TestMethodWorker.java:128)
at java.util.ArrayList.forEach(ArrayList.java:1259)
at org.testng.TestRunner.privateRun(TestRunner.java:770)
at org.testng.TestRunner.run(TestRunner.java:591)
at org.testng.SuiteRunner.runTest(SuiteRunner.java:402)
at org.testng.SuiteRunner.runSequentially(SuiteRunner.java:396)
at org.testng.SuiteRunner.privateRun(SuiteRunner.java:355)
at org.testng.SuiteRunner.run(SuiteRunner.java:304)
at org.testng.SuiteRunnerWorker.runSuite(SuiteRunnerWorker.java:53)
at org.testng.SuiteRunnerWorker.run(SuiteRunnerWorker.java:96)
at org.testng.TestNG.runSuitesSequentially(TestNG.java:1180)
at org.testng.TestNG.runSuitesLocally(TestNG.java:1102)
at org.testng.TestNG.runSuites(TestNG.java:1032)
at org.testng.TestNG.run(TestNG.java:1000)
at org.testng.remote.AbstractRemoteTestNG.run(AbstractRemoteTestNG.java:115)
at org.testng.remote.RemoteTestNG.initAndRun(RemoteTestNG.java:251)
at org.testng.remote.RemoteTestNG.main(RemoteTestNG.java:77)
]]>
            </full-stacktrace>
          </exception> <!-- java.lang.AssertionError -->
          <reporter-output>
          </reporter-output>
        </test-method> <!-- test2_postEmployee -->
        <test-method status="PASS" signature="test3_getIDEmployee()[pri:0, instance:testes.TesteApiDummy@51cdd8a]" name="test3_getIDEmployee" duration-ms="1040" started-at="2022-01-03T00:57:08 BRT" finished-at="2022-01-03T00:57:09 BRT">
          <reporter-output>
          </reporter-output>
        </test-method> <!-- test3_getIDEmployee -->
        <test-method status="FAIL" signature="test4_putEmployee()[pri:0, instance:testes.TesteApiDummy@51cdd8a]" name="test4_putEmployee" duration-ms="1003" started-at="2022-01-03T00:57:09 BRT" finished-at="2022-01-03T00:57:10 BRT">
          <exception class="java.lang.AssertionError">
            <message>
              <![CDATA[expected:<429> but was:<200>]]>
            </message>
            <full-stacktrace>
              <![CDATA[java.lang.AssertionError: expected:<429> but was:<200>
at org.junit.Assert.fail(Assert.java:88)
at org.junit.Assert.failNotEquals(Assert.java:834)
at org.junit.Assert.assertEquals(Assert.java:645)
at org.junit.Assert.assertEquals(Assert.java:631)
at testes.TesteApiDummy.test4_putEmployee(TesteApiDummy.java:96)
at sun.reflect.NativeMethodAccessorImpl.invoke0(Native Method)
at sun.reflect.NativeMethodAccessorImpl.invoke(NativeMethodAccessorImpl.java:62)
at sun.reflect.DelegatingMethodAccessorImpl.invoke(DelegatingMethodAccessorImpl.java:43)
at java.lang.reflect.Method.invoke(Method.java:498)
at org.testng.internal.MethodInvocationHelper.invokeMethod(MethodInvocationHelper.java:133)
at org.testng.internal.TestInvoker.invokeMethod(TestInvoker.java:584)
at org.testng.internal.TestInvoker.invokeTestMethod(TestInvoker.java:172)
at org.testng.internal.MethodRunner.runInSequence(MethodRunner.java:46)
at org.testng.internal.TestInvoker$MethodInvocationAgent.invoke(TestInvoker.java:804)
at org.testng.internal.TestInvoker.invokeTestMethods(TestInvoker.java:145)
at org.testng.internal.TestMethodWorker.invokeTestMethods(TestMethodWorker.java:146)
at org.testng.internal.TestMethodWorker.run(TestMethodWorker.java:128)
at java.util.ArrayList.forEach(ArrayList.java:1259)
at org.testng.TestRunner.privateRun(TestRunner.java:770)
at org.testng.TestRunner.run(TestRunner.java:591)
at org.testng.SuiteRunner.runTest(SuiteRunner.java:402)
at org.testng.SuiteRunner.runSequentially(SuiteRunner.java:396)
at org.testng.SuiteRunner.privateRun(SuiteRunner.java:355)
at org.testng.SuiteRunner.run(SuiteRunner.java:304)
at org.testng.SuiteRunnerWorker.runSuite(SuiteRunnerWorker.java:53)
at org.testng.SuiteRunnerWorker.run(SuiteRunnerWorker.java:96)
at org.testng.TestNG.runSuitesSequentially(TestNG.java:1180)
at org.testng.TestNG.runSuitesLocally(TestNG.java:1102)
at org.testng.TestNG.runSuites(TestNG.java:1032)
at org.testng.TestNG.run(TestNG.java:1000)
at org.testng.remote.AbstractRemoteTestNG.run(AbstractRemoteTestNG.java:115)
at org.testng.remote.RemoteTestNG.initAndRun(RemoteTestNG.java:251)
at org.testng.remote.RemoteTestNG.main(RemoteTestNG.java:77)
]]>
            </full-stacktrace>
          </exception> <!-- java.lang.AssertionError -->
          <reporter-output>
          </reporter-output>
        </test-method> <!-- test4_putEmployee -->
        <test-method status="FAIL" signature="test5_deleteEmployee()[pri:0, instance:testes.TesteApiDummy@51cdd8a]" name="test5_deleteEmployee" duration-ms="995" started-at="2022-01-03T00:57:10 BRT" finished-at="2022-01-03T00:57:11 BRT">
          <exception class="java.lang.AssertionError">
            <message>
              <![CDATA[expected:<429> but was:<200>]]>
            </message>
            <full-stacktrace>
              <![CDATA[java.lang.AssertionError: expected:<429> but was:<200>
at org.junit.Assert.fail(Assert.java:88)
at org.junit.Assert.failNotEquals(Assert.java:834)
at org.junit.Assert.assertEquals(Assert.java:645)
at org.junit.Assert.assertEquals(Assert.java:631)
at testes.TesteApiDummy.test5_deleteEmployee(TesteApiDummy.java:115)
at sun.reflect.NativeMethodAccessorImpl.invoke0(Native Method)
at sun.reflect.NativeMethodAccessorImpl.invoke(NativeMethodAccessorImpl.java:62)
at sun.reflect.DelegatingMethodAccessorImpl.invoke(DelegatingMethodAccessorImpl.java:43)
at java.lang.reflect.Method.invoke(Method.java:498)
at org.testng.internal.MethodInvocationHelper.invokeMethod(MethodInvocationHelper.java:133)
at org.testng.internal.TestInvoker.invokeMethod(TestInvoker.java:584)
at org.testng.internal.TestInvoker.invokeTestMethod(TestInvoker.java:172)
at org.testng.internal.MethodRunner.runInSequence(MethodRunner.java:46)
at org.testng.internal.TestInvoker$MethodInvocationAgent.invoke(TestInvoker.java:804)
at org.testng.internal.TestInvoker.invokeTestMethods(TestInvoker.java:145)
at org.testng.internal.TestMethodWorker.invokeTestMethods(TestMethodWorker.java:146)
at org.testng.internal.TestMethodWorker.run(TestMethodWorker.java:128)
at java.util.ArrayList.forEach(ArrayList.java:1259)
at org.testng.TestRunner.privateRun(TestRunner.java:770)
at org.testng.TestRunner.run(TestRunner.java:591)
at org.testng.SuiteRunner.runTest(SuiteRunner.java:402)
at org.testng.SuiteRunner.runSequentially(SuiteRunner.java:396)
at org.testng.SuiteRunner.privateRun(SuiteRunner.java:355)
at org.testng.SuiteRunner.run(SuiteRunner.java:304)
at org.testng.SuiteRunnerWorker.runSuite(SuiteRunnerWorker.java:53)
at org.testng.SuiteRunnerWorker.run(SuiteRunnerWorker.java:96)
at org.testng.TestNG.runSuitesSequentially(TestNG.java:1180)
at org.testng.TestNG.runSuitesLocally(TestNG.java:1102)
at org.testng.TestNG.runSuites(TestNG.java:1032)
at org.testng.TestNG.run(TestNG.java:1000)
at org.testng.remote.AbstractRemoteTestNG.run(AbstractRemoteTestNG.java:115)
at org.testng.remote.RemoteTestNG.initAndRun(RemoteTestNG.java:251)
at org.testng.remote.RemoteTestNG.main(RemoteTestNG.java:77)
]]>
            </full-stacktrace>
          </exception> <!-- java.lang.AssertionError -->
          <reporter-output>
          </reporter-output>
        </test-method> <!-- test5_deleteEmployee -->
      </class> <!-- testes.TesteApiDummy -->
    </test> <!-- Default test -->
  </suite> <!-- Default suite -->
</testng-results>
